Workbook

Sheet Inputs
A1: Parameter | B1: Value | C1: Notes
A2: N0 (non-experts count) | B2: 70 | C2: Count of non-experts
A3: N1 (experts L1 count) | B3: 15 | C3: Count of experts level 1
A4: N2 (experts L2 count) | B4: 10 | C4: Count of experts level 2
A5: N3 (experts L3 count) | B5: 5 | C5: Count of experts level 3
A7: q0 (quota non-experts) | B7: 0.25 | C7: Share of total base votes
A8: q1 (quota L1) | B8: 0.15 | C8: Share of total base votes
A9: votes | B9: 0.25 | C9: Share of total base votes
A10: q3 (quota L3) | B10: 0.35 | C10: Share of total base votes
A12: floor f1 (>=1) | B12: 1.2 | C12: Guaranteed minimal per-person base weight for L1
A13: floor f2 (>=1) | B13: 2 | C13: Guaranteed minimal per-person base weight for L2
A14: floor f3 (>=1) | B14: 4 | C14: Guaranteed minimal per-person base weight for L3
A15: epsilon_min (increment over 1) | B15: 0.1 | C15: Minimal increment so expert > 1 at all times
... A23: years since confirm L3 | B23: 0 | C23: If 0, no degrade
A25: S = N0/q0 (scale) | B25: =B2/B7 -> 280 | C25: Calculated
A26: P_floor (external buffer) | B26: =0.1*B25 -> 28 | C26: Default 10% of S
A27: P_edu (education pool) | B27: =0.05*B25 -> 14 | C27: Default 5% of S
A28: q_sum check | B28: =B7+B8+B9+B10 -> 1 | C28: Should equal 1.0

Sheet Summary
A1: S (scale N0/q0) | C1: =Inputs!B2/Inputs!B7 -> 280
A2: T0 (target base sum NE) | C2: =Inputs!B25*Inputs!B7 -> 70
A3: T1 (target base sum L1) | C3: =Inputs!B25*Inputs!B8 -> 42
A4: T2 (target base sum L2) | C4: =Inputs!B25*Inputs!B9 -> 70
A5: T3 (target base sum L3) | C5: =Inputs!B25*Inputs!B10 -> 98
A7: f1_eff | C7: =1+MAX( (Inputs!B12-1)*POWER(1-Inputs!B18, IF(Inputs!B17=0,0,Inputs!B21/Inputs!B17)), Inputs!B15) -> 1.2
A8: f2_eff | C8: =1+MAX( (Inputs!B13-1)*POWER(1-Inputs!B19, IF(Inputs!B17=0,0,Inputs!B22/Inputs!B17)), Inputs!B15) -> 2
A9: f3_eff | C9: =1+MAX( (Inputs!B14-1)*POWER(1-Inputs!B20, IF(Inputs!B17=0,0,Inputs!B23/Inputs!B17)), Inputs!B15) -> 4
A11: N0 | C11: =Inputs!B2 -> 70
A12: N1 | C12: =Inputs!B3 -> 15
A13: N2 | C13: =Inputs!B4 -> 10
A14: N3 | C14: =Inputs!B5 -> 5
A16: F0 (NE sum @1) | C16: =Summary!C11*1 -> 70
A17: F1 = N1*f1_eff | C17: =Summary!C12*Summary!C7 -> 18
A18: F2 = N2*f2_eff | C18: =Summary!C13*Summary!C8 -> 20
A19: F3 = N3*f3_eff | C19: =Summary!C14*Summary!C9 -> 20
A21: w0_base (NE per-person) | C21: =1 -> 1
A22: w1_base | C22: =IF(Summary!C17<=Summary!C3, Summary!C7 + (Summary!C3 - Summary!C17)/Summary!C12, Summary!C7) -> 2.8
A23: w2_base | C23: =IF(Summary!C18<=Summary!C4, Summary!C8 + (Summary!C4 - Summary!C18)/Summary!C13, Summary!C8) -> 7
A24: w3_base | C24: =IF(Summary!C19<=Summary!C5, Summary!C9 + (Summary!C5 - Summary!C19)/Summary!C14, Summary!C9) -> 19.6
A26: delta1 overload | C26: =MAX(Summary!C17 - Summary!C3, 0) -> 0
A27: delta2 overload | C27: =MAX(Summary!C18 - Summary!C4, 0) -> 0
A28: delta3 overload | C28: =MAX(Summary!C19 - Summary!C5, 0) -> 0
A29: Total overload | C29: =Summary!C26+Summary!C27+Summary!C28 -> 0
A30: P_floor available | C30: =Inputs!B26 -> 28
A31: Uncovered overload (warning) | C31: =MAX(Summary!C29 - Summary!C30, 0) -> 0
A33: Base sum NE (quota) | C33: =Summary!C2 -> 70
A34: Base sum L1 (quota) | C34: =Summary!C3 -> 42
A35: Base sum L2 (quota) | C35: =Summary!C4 -> 70
A36: Base sum L3 (quota) | C36: =Summary!C5 -> 98
A37: Actual base sum NE | C37: =Summary!C11*Summary!C21 -> 70
A38: Actual base sum L1 | C38: =Summary!C12*Summary!C22 -> 42
A39: Actual base sum L2 | C39: =Summary!C13*Summary!C23 -> 70
A40: Actual base sum L3 | C40: =Summary!C14*Summary!C24 -> 98
A42: P_edu (education pool) | C42: =Inputs!B27 -> 14
A43: Sum of positive s_i (Individuals) | C43: =SUMIF(Individuals!C:C,">0",Individuals!C:C) -> 1.5

Sheet Individuals
A1: person_id | B1: level (0/1/2/3) | C1: s_i (education score -1..1) | D1: years_since_confirm (optional) | E1: w_base (linked) | F1: b_i (P_edu share) | G1: w_total
A2: alice | B2: 0 | C2: 0 | E2: =IF(B2=0, Summary!B20, IF(B2=1, Summary!B21, IF(B2=2, Summary!B22, IF(B2=3, Summary!B23, "")))) | F2: =IF(C2>0, Summary!B36 * C2 / IF(Summary!B37=0, 1, Summary!B37), 0) -> 0 | G2: =IF(E2="", "", E2+F2)
A3: bob | B3: 1 | C3: 0.2 | D3: 0 | E3: =IF(B3=0, Summary!B20, IF(B3=1, Summary!B21, IF(B3=2, Summary!B22, IF(B3=3, Summary!B23, "")))) | F3: =IF(C3>0, Summary!B36 * C3 / IF(Summary!B37=0, 1, Summary!B37), 0) -> 0 | G3: =IF(E3="", "", E3+F3)
A4: carol | B4: 2 | C4: 0.8 | D4: 3 | E4: =IF(B4=0, Summary!B20, IF(B4=1, Summary!B21, IF(B4=2, Summary!B22, IF(B4=3, Summary!B23, "")))) | F4: =IF(C4>0, Summary!B36 * C4 / IF(Summary!B37=0, 1, Summary!B37), 0) -> 0 | G4: =IF(E4="", "", E4+F4)
A5: dan | B5: 3 | C5: 0.5 | D5: 8 | E5: =IF(B5=0, Summary!B20, IF(B5=1, Summary!B21, IF(B5=2, Summary!B22, IF(B5=3, Summary!B23, "")))) | F5: =IF(C5>0, Summary!B36 * C5 / IF(Summary!B37=0, 1, Summary!B37), 0) -> 0 | G5: =IF(E5="", "", E5+F5)
A6: eva | B6: 1 | C6: -0.1 | D6: 1 | E6: =IF(B6=0, Summary!B20, IF(B6=1, Summary!B21, IF(B6=2, Summary!B22, IF(B6=3, Summary!B23, "")))) | F6: =IF(C6>0, Summary!B36 * C6 / IF(Summary!B37=0, 1, Summary!B37), 0) -> 0 | G6: =IF(E6="", "", E6+F6)
E7: =IF(B7=0, Summary!B20, IF(B7=1, Summary!B21, IF(B7=2, Summary!B22, IF(B7=3, Summary!B23, "")))) | F7: =IF(C7>0, Summary!B36 * C7 / IF(Summary!B37=0, 1, Summary!B37), 0) -> 0 | G7: =IF(E7="", "", E7+F7)
E8: =IF(B8=0, Summary!B20, IF(B8=1, Summary!B21, IF(B8=2, Summary!B22, IF(B8=3, Summary!B23, "")))) | F8: =IF(C8>0, Summary!B36 * C8 / IF(Summary!B37=0, 1, Summary!B37), 0) -> 0 | G8: =IF(E8="", "", E8+F8)
E9: =IF(B9=0, Summary!B20, IF(B9=1, Summary!B21, IF(B9=2, Summary!B22, IF(B9=3, Summary!B23, "")))) | F9: =IF(C9>0, Summary!B36 * C9 / IF(Summary!B37=0, 1, Summary!B37), 0) -> 0 | G9: =IF(E9="", "", E9+F9)
E10: =IF(B10=0, Summary!B20, IF(B10=1, Summary!B21, IF(B10=2, Summary!B22, IF(B10=3, Summary!B23, "")))) | F10: =IF(C10>0, Summary!B36 * C10 / IF(Summary!B37=0, 1, Summary!B37), 0) -> 0 | G10: =IF(E10="", "", E10+F10)
E11: =IF(B11=0, Summary!B20, IF(B11=1, Summary!B21, IF(B11=2, Summary!B22, IF(B11=3, Summary!B23, "")))) | F11: =IF(C11>0, Summary!B36 * C11 / IF(Summary!B37=0, 1, Summary!B37), 0) -> 0 | G11: =IF(E11="", "", E11+F11)
E12: =IF(B12=0, Summary!B20, IF(B12=1, Summary!B21, IF(B12=2, Summary!B22, IF(B12=3, Summary!B23, "")))) | F12: =IF(C12>0, Summary!B36 * C12 / IF(Summary!B37=0, 1, Summary!B37), 0) -> 0 | G12: =IF(E12="", "", E12+F12)
E13: =IF(B13=0, Summary!B20, IF(B13=1, Summary!B21, IF(B13=2, Summary!B22, IF(B13=3, Summary!B23, "")))) | F13: =IF(C13>0, Summary!B36 * C13 / IF(Summary!B37=0, 1, Summary!B37), 0) -> 0 | G13: =IF(E13="", "", E13+F13)
E14: =IF(B14=0, Summary!B20, IF(B14=1, Summary!B21, IF(B14=2, Summary!B22, IF(B14=3, Summary!B23, "")))) | F14: =IF(C14>0, Summary!B36 * C14 / IF(Summary!B37=0, 1, Summary!B37), 0) -> 0 | G14: =IF(E14="", "", E14+F14)
E15: =IF(B15=0, Summary!B20, IF(B15=1, Summary!B21, IF(B15=2, Summary!B22, IF(B15=3, Summary!B23, "")))) | F15: =IF(C15>0, Summary!B36 * C15 / IF(Summary!B37=0, 1, Summary!B37), 0) -> 0 | G15: =IF(E15="", "", E15+F15)
E16: =IF(B16=0, Summary!B20, IF(B16=1, Summary!B21, IF(B16=2, Summary!B22, IF(B16=3, Summary!B23, "")))) | F16: =IF(C16>0, Summary!B36 * C16 / IF(Summary!B37=0, 1, Summary!B37), 0) -> 0 | G16: =IF(E16="", "", E16+F16)
E17: =IF(B17=0, Summary!B20, IF(B17=1, Summary!B21, IF(B17=2, Summary!B22, IF(B17=3, Summary!B23, "")))) | F17: =IF(C17>0, Summary!B36 * C17 / IF(Summary!B37=0, 1, Summary!B37), 0) -> 0 | G17: =IF(E17="", "", E17+F17)
E18: =IF(B18=0, Summary!B20, IF(B18=1, Summary!B21, IF(B18=2, Summary!B22, IF(B18=3, Summary!B23, "")))) | F18: =IF(C18>0, Summary!B36 * C18 / IF(Summary!B37=0, 1, Summary!B37), 0) -> 0 | G18: =IF(E18="", "", E18+F18)
E19: =IF(B19=0, Summary!B20, IF(B19=1, Summary!B21, IF(B19=2, Summary!B22, IF(B19=3, Summary!B23, "")))) | F19: =IF(C19>0, Summary!B36 * C19 / IF(Summary!B37=0, 1, Summary!B37), 0) -> 0 | G19: =IF(E19="", "", E19+F19)
E20: =IF(B20=0, Summary!B20, IF(B20=1, Summary!B21, IF(B20=2, Summary!B22, IF(B20=3, Summary!B23, "")))) | F20: =IF(C20>0, Summary!B36 * C20 / IF(Summary!B37=0, 1, Summary!B37), 0) -> 0 | G20: =IF(E20="", "", E20+F20)
E21: =IF(B21=0, Summary!B20, IF(B21=1, Summary!B21, IF(B21=2, Summary!B22, IF(B21=3, Summary!B23, "")))) | F21: =IF(C21>0, Summary!B36 * C21 / IF(Summary!B37=0, 1, Summary!B37), 0) -> 0 | G21: =IF(E21="", "", E21+F21)
E22: =IF(B22=0, Summary!B20, IF(B22=1, Summary!B21, IF(B22=2, Summary!B22, IF(B22=3, Summary!B23, "")))) | F22: =IF(C22>0, Summary!B36 * C22 / IF(Summary!B37=0, 1, Summary!B37), 0) -> 0 | G22: =IF(E22="", "", E22+F22)
E23: =IF(B23=0, Summary!B20, IF(B23=1, Summary!B21, IF(B23=2, Summary!B22, IF(B23=3, Summary!B23, "")))) | F23: =IF(C23>0, Summary!B36 * C23 / IF(Summary!B37=0, 1, Summary!B37), 0) -> 0 | G23: =IF(E23="", "", E23+F23)
E24: =IF(B24=0, Summary!B20, IF(B24=1, Summary!B21, IF(B24=2, Summary!B22, IF(B24=3, Summary!B23, "")))) | F24: =IF(C24>0, Summary!B36 * C24 / IF(Summary!B37=0, 1, Summary!B37), 0) -> 0 | G24: =IF(E24="", "", E24+F24)
E25: =IF(B25=0, Summary!B20, IF(B25=1, Summary!B21, IF(B25=2, Summary!B22, IF(B25=3, Summary!B23, "")))) | F25: =IF(C25>0, Summary!B36 * C25 / IF(Summary!B37=0, 1, Summary!B37), 0) -> 0 | G25: =IF(E25="", "", E25+F25)
E26: =IF(B26=0, Summary!B20, IF(B26=1, Summary!B21, IF(B26=2, Summary!B22, IF(B26=3, Summary!B23, "")))) | F26: =IF(C26>0, Summary!B36 * C26 / IF(Summary!B37=0, 1, Summary!B37), 0) -> 0 | G26: =IF(E26="", "", E26+F26)
E27: =IF(B27=0, Summary!B20, IF(B27=1, Summary!B21, IF(B27=2, Summary!B22, IF(B27=3, Summary!B23, "")))) | F27: =IF(C27>0, Summary!B36 * C27 / IF(Summary!B37=0, 1, Summary!B37), 0) -> 0 | G27: =IF(E27="", "", E27+F27)
E28: =IF(B28=0, Summary!B20, IF(B28=1, Summary!B21, IF(B28=2, Summary!B22, IF(B28=3, Summary!B23, "")))) | F28: =IF(C28>0, Summary!B36 * C28 / IF(Summary!B37=0, 1, Summary!B37), 0) -> 0 | G28: =IF(E28="", "", E28+F28)
E29: =IF(B29=0, Summary!B20, IF(B29=1, Summary!B21, IF(B29=2, Summary!B22, IF(B29=3, Summary!B23, "")))) | F29: =IF(C29>0, Summary!B36 * C29 / IF(Summary!B37=0, 1, Summary!B37), 0) -> 0 | G29: =IF(E29="", "", E29+F29)
E30: =IF(B30=0, Summary!B20, IF(B30=1, Summary!B21, IF(B30=2, Summary!B22, IF(B30=3, Summary!B23, "")))) | F30: =IF(C30>0, Summary!B36 * C30 / IF(Summary!B37=0, 1, Summary!B37), 0) -> 0 | G30: =IF(E30="", "", E30+F30)
E31: =IF(B31=0, Summary!B20, IF(B31=1, Summary!B21, IF(B31=2, Summary!B22, IF(B31=3, Summary!B23, "")))) | F31: =IF(C31>0, Summary!B36 * C31 / IF(Summary!B37=0, 1, Summary!B37), 0) -> 0 | G31: =IF(E31="", "", E31+F31)
E32: =IF(B32=0, Summary!B20, IF(B32=1, Summary!B21, IF(B32=2, Summary!B22, IF(B32=3, Summary!B23, "")))) | F32: =IF(C32>0, Summary!B36 * C32 / IF(Summary!B37=0, 1, Summary!B37), 0) -> 0 | G32: =IF(E32="", "", E32+F32)
E33: =IF(B33=0, Summary!B20, IF(B33=1, Summary!B21, IF(B33=2, Summary!B22, IF(B33=3, Summary!B23, "")))) | F33: =IF(C33>0, Summary!B36 * C33 / IF(Summary!B37=0, 1, Summary!B37), 0) -> 0 | G33: =IF(E33="", "", E33+F33)
E34: =IF(B34=0, Summary!B20, IF(B34=1, Summary!B21, IF(B34=2, Summary!B22, IF(B34=3, Summary!B23, "")))) | F34: =IF(C34>0, Summary!B36 * C34 / IF(Summary!B37=0, 1, Summary!B37), 0) -> 0 | G34: =IF(E34="", "", E34+F34)
E35: =IF(B35=0, Summary!B20, IF(B35=1, Summary!B21, IF(B35=2, Summary!B22, IF(B35=3, Summary!B23, "")))) | F35: =IF(C35>0, Summary!B36 * C35 / IF(Summary!B37=0, 1, Summary!B37), 0) -> 0 | G35: =IF(E35="", "", E35+F35)
E36: =IF(B36=0, Summary!B20, IF(B36=1, Summary!B21, IF(B36=2, Summary!B22, IF(B36=3, Summary!B23, "")))) | F36: =IF(C36>0, Summary!B36 * C36 / IF(Summary!B37=0, 1, Summary!B37), 0) -> 0 | G36: =IF(E36="", "", E36+F36)
E37: =IF(B37=0, Summary!B20, IF(B37=1, Summary!B21, IF(B37=2, Summary!B22, IF(B37=3, Summary!B23, "")))) | F37: =IF(C37>0, Summary!B36 * C37 / IF(Summary!B37=0, 1, Summary!B37), 0) -> 0 | G37: =IF(E37="", "", E37+F37)
E38: =IF(B38=0, Summary!B20, IF(B38=1, Summary!B21, IF(B38=2, Summary!B22, IF(B38=3, Summary!B23, "")))) | F38: =IF(C38>0, Summary!B36 * C38 / IF(Summary!B37=0, 1, Summary!B37), 0) -> 0 | G38: =IF(E38="", "", E38+F38)
E39: =IF(B39=0, Summary!B20, IF(B39=1, Summary!B21, IF(B39=2, Summary!B22, IF(B39=3, Summary!B23, "")))) | F39: =IF(C39>0, Summary!B36 * C39 / IF(Summary!B37=0, 1, Summary!B37), 0) -> 0 | G39: =IF(E39="", "", E39+F39)
E40: =IF(B40=0, Summary!B20, IF(B40=1, Summary!B21, IF(B40=2, Summary!B22, IF(B40=3, Summary!B23, "")))) | F40: =IF(C40>0, Summary!B36 * C40 / IF(Summary!B37=0, 1, Summary!B37), 0) -> 0 | G40: =IF(E40="", "", E40+F40)
...
